<?xml version="1.0" ?>
<!-- =================================================================================== -->
<!-- |    This document was autogenerated by xacro from /home/li-wen/avatar_ws_backup_2/install/avatar_moveit_config/share/avatar_moveit_config/config/avatar.urdf.xacro | -->
<!-- |    EDITING THIS FILE BY HAND IS NOT RECOMMENDED                                 | -->
<!-- =================================================================================== -->
<robot name="left_arm" xmlns:controller="http://playerstage.sourceforge.net/gazebo/xmlschema/#controller" xmlns:interface="http://playerstage.sourceforge.net/gazebo/xmlschema/#interface" xmlns:sensor="http://playerstage.sourceforge.net/gazebo/xmlschema/#sensor">
  
  <material name="Blue">
    <color rgba="0.0 0.0 0.8 1.0"/>
  </material>
  <material name="Green">
    <color rgba="0.0 0.8 0.0 1.0"/>
  </material>
  <material name="BiotacGreen">
    <color rgba="0.31 0.85 0.42 1.0"/>
  </material>
  <material name="Grey">
    <color rgba="0.2 0.2 0.2 1.0"/>
  </material>
  <material name="LightGrey">
    <color rgba="0.6 0.6 0.6 1.0"/>
  </material>
  <material name="Red">
    <color rgba="0.8 0.0 0.0 1.0"/>
  </material>
  <material name="White">
    <color rgba="1.0 1.0 1.0 1.0"/>
  </material>
  
  <gazebo>
    <plugin filename="libgazebo_ros_control.so" name="gazebo_ros_control">
      <robotSimType>sr_gazebo_sim/SrGazeboHWSim</robotSimType>
    </plugin>
  </gazebo>
  
  <!-- Conversion were obtained from http://www.e-paint.co.uk/Lab_values.asp
       unless otherwise stated. -->
  <!-- link list -->
  <link name="gofa1_base">
    <!-- See note 1 in package.xml about the inertial and mass values -->
    <inertial>
      <mass value="3.50083457958494"/>
      <origin xyz="-0.0012013793465437 -0.000175191786981708 0.0862146007385352"/>
      <inertia ixx="0.0153015257917955" ixy="-6.40155032892694E-05" ixz="-0.000276708687772683" iyy="0.0159333503953857" iyz="-3.98029144780725E-05" izz="0.0112162302268266"/>
    </inertial>
    <collision name="collision">
      <geometry>
        <mesh filename="package://abb_gofa_support/meshes/gofa/collision/base_from_STL.obj"/>
      </geometry>
    </collision>
    <visual name="visual">
      <geometry>
        <mesh filename="package://abb_gofa_support/meshes/gofa/visual/base_from_STL.obj"/>
      </geometry>
      <material name="">
        <color rgba="1 1 0 1"/>
      </material>
    </visual>
  </link>
  <link name="gofa1_link_1">
    <!-- See note 1 in package.xml about the inertial and mass values -->
    <inertial>
      <mass value="2.76743491139404"/>
      <origin xyz="2.08682453325091E-06 0.0103608399967513 0.0705307203199506"/>
      <inertia ixx="0.0115158625894577" ixy="6.37197693598838E-08" ixz="5.98954393680154E-09" iyy="0.006494848329231" iyz="-0.000196668400316843" izz="0.0109446835358581"/>
    </inertial>
    <collision name="collision">
      <geometry>
        <mesh filename="package://abb_gofa_support/meshes/gofa/collision/link_1_from_STL.obj"/>
      </geometry>
    </collision>
    <visual name="visual">
      <geometry>
        <mesh filename="package://abb_gofa_support/meshes/gofa/visual/link_1_from_STL.obj"/>
      </geometry>
      <material name="">
        <color rgba="1 1 0 1"/>
      </material>
    </visual>
  </link>
  <link name="gofa1_link_2">
    <!-- See note 1 in package.xml about the inertial and mass values -->
    <inertial>
      <mass value="4.2890416"/>
      <origin xyz="1.34018352211628E-06 -0.0500118376116071 0.222001399322246"/>
      <inertia ixx="0.130524729873898" ixy="1.31811857134115E-07" ixz="1.99022457670482E-06" iyy="0.133278449324229" iyz="-4.48622200366709E-07" izz="0.00669457974697178"/>
    </inertial>
    <collision name="collision">
      <geometry>
        <mesh filename="package://abb_gofa_support/meshes/gofa/collision/link_2_from_STL.obj"/>
      </geometry>
    </collision>
    <visual name="visual">
      <geometry>
        <mesh filename="package://abb_gofa_support/meshes/gofa/visual/link_2_from_STL.obj"/>
      </geometry>
      <material name="">
        <color rgba="1 1 0 1"/>
      </material>
    </visual>
  </link>
  <link name="gofa1_link_3">
    <!-- See note 1 in package.xml about the inertial and mass values -->
    <inertial>
      <mass value="3.38333107992875"/>
      <origin xyz="0.0128129281453599 0.0944171780907046 0.0247427540642403"/>
      <inertia ixx="0.0175626138728642" ixy="0.000364866179108744" ixz="-0.00318670290285352" iyy="0.0140230068919562" iyz="0.000704668055158407" izz="0.013275205067567"/>
    </inertial>
    <collision name="collision">
      <geometry>
        <mesh filename="package://abb_gofa_support/meshes/gofa/collision/link_3_from_STL.obj"/>
      </geometry>
    </collision>
    <visual name="visual">
      <geometry>
        <mesh filename="package://abb_gofa_support/meshes/gofa/visual/link_3_from_STL.obj"/>
      </geometry>
      <material name="">
        <color rgba="1 1 0 1"/>
      </material>
    </visual>
  </link>
  <link name="gofa1_link_4">
    <!-- See note 1 in package.xml about the inertial and mass values -->
    <inertial>
      <mass value="2.77857535641324"/>
      <origin xyz="0.160558561602322 0.041976811408979 -2.36623354021859E-07"/>
      <inertia ixx="0.00881683095901354" ixy="-0.010746260580237" ixz="1.2899930119841E-07" iyy="0.0340754175571832" iyz="3.96362791626429E-08" izz="0.0389358932156922"/>
    </inertial>
    <collision name="collision">
      <geometry>
        <mesh filename="package://abb_gofa_support/meshes/gofa/collision/link_4_from_STL.obj"/>
      </geometry>
    </collision>
    <visual name="visual">
      <geometry>
        <mesh filename="package://abb_gofa_support/meshes/gofa/visual/link_4_from_STL.obj"/>
      </geometry>
      <material name="">
        <color rgba="1 1 0 1"/>
      </material>
    </visual>
  </link>
  <link name="gofa1_link_5">
    <!-- See note 1 in package.xml about the inertial and mass values -->
    <inertial>
      <mass value="3.01105814739001"/>
      <origin xyz="-0.0147152361879962 -0.0785646469392633 0.0427558021601431"/>
      <inertia ixx="0.0114597336686444" ixy="0.000180094704361231" ixz="0.00165207280226761" iyy="0.013561904467501" iyz="-0.000525272443978826" izz="0.0108480119549914"/>
    </inertial>
    <collision name="collision">
      <geometry>
        <mesh filename="package://abb_gofa_support/meshes/gofa/collision/link_5_from_STL.obj"/>
      </geometry>
    </collision>
    <visual name="visual">
      <geometry>
        <mesh filename="package://abb_gofa_support/meshes/gofa/visual/link_5_from_STL.obj"/>
      </geometry>
      <material name="">
        <color rgba="1 1 0 1"/>
      </material>
    </visual>
  </link>
  <link name="gofa1_link_6">
    <!-- See note 1 in package.xml about the inertial and mass values -->
    <inertial>
      <mass value="0.146500988015653"/>
      <origin rpy="0 0 0" xyz="0.0137506852604966 0.000239804131398652 -0.000341962798940165"/>
      <inertia ixx="0.000128977630055306" ixy="-8.7622752508613E-08" ixz="1.18851551870012E-07" iyy="7.61118177829087E-05" iyz="-6.49821554399679E-07" izz="7.65022909768016E-05"/>
    </inertial>
    <!-- Meshlab calculated values (below) make gazebo crash when rotating this joint. -->
    <!-- <inertial>
        <mass value="0.00686711"/>
        <origin xyz="-0.00250976 -1.89e-06 0.00010218"/>
        <inertia ixx="1.3517e-06" ixy="-1.21316e-11" ixz="9.18065e-12" iyy="6.89813e-07" iyz="-1.21534e-10" izz="6.90097e-07"/>
      </inertial> -->
    <collision name="collision">
      <geometry>
        <mesh filename="package://abb_gofa_support/meshes/gofa/collision/link_6_from_STL.obj"/>
      </geometry>
    </collision>
    <visual name="visual">
      <geometry>
        <mesh filename="package://abb_gofa_support/meshes/gofa/visual/link_6_from_STL.obj"/>
      </geometry>
      <material name="">
        <color rgba="1 1 0 1"/>
      </material>
    </visual>
  </link>
  <!-- end of link list -->
  <!-- joint list -->
  <joint name="gofa1_joint_1" type="revolute">
    <origin rpy="0 0 0" xyz="0 0 0.1875"/>
    <axis xyz="0 0 1"/>
    <parent link="gofa1_base"/>
    <child link="gofa1_link_1"/>
    <!-- See note 2 in package.xml about effort limits and dynamics values -->
    <limit effort="1000" lower="-2.967" upper="2.967" velocity="5.027"/>
    <dynamics damping="50.0" friction="1.0"/>
  </joint>
  <joint name="gofa1_joint_2" type="revolute">
    <origin rpy="0 0 0" xyz="0 -0.085 0.0775"/>
    <axis xyz="0 1 0"/>
    <parent link="gofa1_link_1"/>
    <child link="gofa1_link_2"/>
    <!-- See note 2 in package.xml about effort limits and dynamics values -->
    <limit effort="1000" lower="-1.745" upper="2.269" velocity="4.189"/>
    <dynamics damping="50.0" friction="1.0"/>
  </joint>
  <joint name="gofa1_joint_3" type="revolute">
    <origin rpy="0 0 0" xyz="0 -0.00100000000000007 0.444"/>
    <axis xyz="0 1 0"/>
    <parent link="gofa1_link_2"/>
    <child link="gofa1_link_3"/>
    <!-- See note 2 in package.xml about effort limits and dynamics values -->
    <limit effort="1000" lower="-3.491" upper="1.222" velocity="5.236"/>
    <dynamics damping="10.0" friction="1.0"/>
  </joint>
  <joint name="gofa1_joint_4" type="revolute">
    <origin rpy="0 0 0" xyz="0.096 0.0860000000000001 0.11"/>
    <axis xyz="1 0 0"/>
    <parent link="gofa1_link_3"/>
    <child link="gofa1_link_4"/>
    <!-- See note 2 in package.xml about effort limits and dynamics values -->
    <limit effort="1000" lower="-4.712" upper="4.712" velocity="6.981"/>
    <dynamics damping="5.0" friction="1.0"/>
  </joint>
  <joint name="gofa1_joint_5" type="revolute">
    <origin rpy="0 0 0" xyz="0.374 0.0744999999999998 0"/>
    <axis xyz="0 1 0"/>
    <parent link="gofa1_link_4"/>
    <child link="gofa1_link_5"/>
    <!-- See note 2 in package.xml about effort limits and dynamics values -->
    <limit effort="1000" lower="-2.269" upper="2.269" velocity="7.069"/>
    <dynamics damping="2.0" friction="1.0"/>
  </joint>
  <joint name="gofa1_joint_6" type="revolute">
    <origin rpy="0 0 0" xyz="0.0679999999999995 -0.0744999999999998 0.0800000000000003"/>
    <axis xyz="1 0 0"/>
    <parent link="gofa1_link_5"/>
    <child link="gofa1_link_6"/>
    <!-- See note 2 in package.xml about effort limits and dynamics values -->
    <limit effort="1000" lower="-6.283" upper="6.283" velocity="10.472"/>
    <dynamics damping="1.0" friction="1.0"/>
  </joint>
  <!-- end of joint list -->
  <!-- gofa transmission list -->
  <!--added by LiWen on Apr 16 2025 -->
  <transmission name="gofa1_joint_1_transmission">
    <type>sr_mechanism_model/SimpleTransmission</type>
    <actuator name="gofa1_J1">
      <mechanicalReduction>1</mechanicalReduction>
    </actuator>
    <joint name="gofa1_joint_1">
      <hardwareInterface>EffortJointInterface</hardwareInterface>
      <hardwareInterface>PositionJointInterface</hardwareInterface>
    </joint>
  </transmission>
  <transmission name="gofa1_joint_2_transmission">
    <type>sr_mechanism_model/SimpleTransmission</type>
    <actuator name="gofa1_J2">
      <mechanicalReduction>1</mechanicalReduction>
    </actuator>
    <joint name="gofa1_joint_2">
      <hardwareInterface>EffortJointInterface</hardwareInterface>
      <hardwareInterface>PositionJointInterface</hardwareInterface>
    </joint>
  </transmission>
  <transmission name="gofa1_joint_3_transmission">
    <type>sr_mechanism_model/SimpleTransmission</type>
    <actuator name="gofa1_J3">
      <mechanicalReduction>1</mechanicalReduction>
    </actuator>
    <joint name="gofa1_joint_3">
      <hardwareInterface>EffortJointInterface</hardwareInterface>
      <hardwareInterface>PositionJointInterface</hardwareInterface>
    </joint>
  </transmission>
  <transmission name="gofa1_joint_4_transmission">
    <type>sr_mechanism_model/SimpleTransmission</type>
    <actuator name="gofa1_J4">
      <mechanicalReduction>1</mechanicalReduction>
    </actuator>
    <joint name="gofa1_joint_4">
      <hardwareInterface>EffortJointInterface</hardwareInterface>
      <hardwareInterface>PositionJointInterface</hardwareInterface>
    </joint>
  </transmission>
  <transmission name="gofa1_joint_5_transmission">
    <type>sr_mechanism_model/SimpleTransmission</type>
    <actuator name="gofa1_J5">
      <mechanicalReduction>1</mechanicalReduction>
    </actuator>
    <joint name="gofa1_joint_5">
      <hardwareInterface>EffortJointInterface</hardwareInterface>
      <hardwareInterface>PositionJointInterface</hardwareInterface>
    </joint>
  </transmission>
  <transmission name="gofa1_joint_6_transmission">
    <type>sr_mechanism_model/SimpleTransmission</type>
    <actuator name="gofa1_J6">
      <mechanicalReduction>1</mechanicalReduction>
    </actuator>
    <joint name="gofa1_joint_6">
      <hardwareInterface>EffortJointInterface</hardwareInterface>
      <hardwareInterface>PositionJointInterface</hardwareInterface>
    </joint>
  </transmission>
  <!-- end of gofa transmission list -->
  <!-- ROS-Industrial 'base' frame- base_link to ABB World Coordinates transform -->
  <link name="gofa1_base_link"/>
  <joint name="gofa1_base_link-base" type="fixed">
    <origin rpy="0 0 0" xyz="0 0 0"/>
    <parent link="gofa1_base_link"/>
    <child link="gofa1_base"/>
  </joint>
  <!-- ROS-Industrial 'tool0' frame- all-zeros tool frame -->
  <link name="gofa1_tool0"/>
  <joint name="gofa1_link_6-tool0" type="fixed">
    <origin rpy="0 1.5708 0" xyz="0.0326 0 0"/>
    <parent link="gofa1_link_6"/>
    <child link="gofa1_tool0"/>
  </joint>
  
</robot>
