<?xml version="1.0" ?>
<!-- =================================================================================== -->
<!-- |    This document was autogenerated by xacro from /home/li-wen/avatar_ws_backup_2/install/avatar_moveit_config/share/avatar_moveit_config/config/avatar.urdf.xacro | -->
<!-- |    EDITING THIS FILE BY HAND IS NOT RECOMMENDED                                 | -->
<!-- =================================================================================== -->
<robot name="neck" xmlns:controller="http://playerstage.sourceforge.net/gazebo/xmlschema/#controller" xmlns:interface="http://playerstage.sourceforge.net/gazebo/xmlschema/#interface" xmlns:sensor="http://playerstage.sourceforge.net/gazebo/xmlschema/#sensor">
  
  <material name="Blue">
    <color rgba="0.0 0.0 0.8 1.0"/>
  </material>
  <material name="Green">
    <color rgba="0.0 0.8 0.0 1.0"/>
  </material>
  <material name="BiotacGreen">
    <color rgba="0.31 0.85 0.42 1.0"/>
  </material>
  <material name="Grey">
    <color rgba="0.2 0.2 0.2 1.0"/>
  </material>
  <material name="LightGrey">
    <color rgba="0.6 0.6 0.6 1.0"/>
  </material>
  <material name="Red">
    <color rgba="0.8 0.0 0.0 1.0"/>
  </material>
  <material name="White">
    <color rgba="1.0 1.0 1.0 1.0"/>
  </material>
  <gazebo>
    <plugin filename="libgazebo_ros_control.so" name="gazebo_ros_control">
      <robotSimType>sr_gazebo_sim/SrGazeboHWSim</robotSimType>
    </plugin>
  </gazebo>
  
  
  <material name="xarm6_Black">
    <color rgba="0.0 0.0 0.0 1.0"/>
  </material>
  <material name="xarm6_Red">
    <color rgba="0.8 0.0 0.0 1.0"/>
  </material>
  <material name="xarm6_White">
    <color rgba="1.0 1.0 1.0 1.0"/>
  </material>
  <material name="xarm6_Silver">
    <color rgba="0.753 0.753 0.753 1.0"/>
  </material>
  <link name="xarm6_link_base">
    <inertial>
      <origin rpy="0 0 0" xyz="0.0 0.0 0.09103"/>
      <mass value="2.7"/>
      <inertia ixx="0.00494875" ixy="-3.5E-06" ixz="1.25E-05" iyy="0.00494174" iyz="1.67E-06" izz="0.002219"/>
    </inertial>
    <visual>
      <geometry>
        <mesh filename="file:///home/li-wen/avatar_ws_backup_2/install/xarm_description/share/xarm_description/meshes/xarm6/visual/link_base_from_stl.obj"/>
      </geometry>
      <origin rpy="0 0 0" xyz="0 0 0"/>
      <material name="xarm6_White"/>
    </visual>
    <collision>
      <geometry>
        <mesh filename="file:///home/li-wen/avatar_ws_backup_2/install/xarm_description/share/xarm_description/meshes/xarm6/visual/link_base_from_stl.obj"/>
      </geometry>
      <origin rpy="0 0 0" xyz="0 0 0"/>
    </collision>
  </link>
  <link name="xarm6_link1">
    <inertial>
      <origin rpy="0 0 0" xyz="0.00022 0.02951 -0.0124"/>
      <mass value="2.3814"/>
      <inertia ixx="0.0058562" ixy="-1.79e-05" ixz="3.55e-06" iyy="0.0050316" iyz="-0.000888336" izz="0.003536652"/>
    </inertial>
    <visual>
      <geometry>
        <mesh filename="file:///home/li-wen/avatar_ws_backup_2/install/xarm_description/share/xarm_description/meshes/xarm6/visual/link1_from_stl.obj"/>
      </geometry>
      <origin rpy="0 0 0" xyz="0 0 0"/>
      <material name="xarm6_White"/>
    </visual>
    <collision>
      <geometry>
        <mesh filename="file:///home/li-wen/avatar_ws_backup_2/install/xarm_description/share/xarm_description/meshes/xarm6/visual/link1_from_stl.obj"/>
      </geometry>
      <origin rpy="0 0 0" xyz="0 0 0"/>
    </collision>
  </link>
  <joint name="xarm6_joint1" type="revolute">
    <parent link="xarm6_link_base"/>
    <child link="xarm6_link1"/>
    <origin rpy="0 0 0" xyz="0 0 0.267"/>
    <axis xyz="0 0 1"/>
    <limit effort="50.0" lower="-6.283185307179586" upper="6.283185307179586" velocity="3.14"/>
    <dynamics damping="1.0" friction="1.0"/>
  </joint>
  <link name="xarm6_link2">
    <inertial>
      <origin rpy="0 0 0" xyz="0.03881 -0.22783 0.03496"/>
      <mass value="2.2675"/>
      <inertia ixx="0.028315776" ixy="0.005" ixz="0.00066546" iyy="0.0058" iyz="-0.0045741" izz="0.0273447"/>
    </inertial>
    <visual>
      <geometry>
        <mesh filename="file:///home/li-wen/avatar_ws_backup_2/install/xarm_description/share/xarm_description/meshes/xarm6/visual/link2_from_stl.obj"/>
      </geometry>
      <origin rpy="0 0 0" xyz="0 0 0"/>
      <material name="xarm6_White"/>
    </visual>
    <collision>
      <geometry>
        <mesh filename="file:///home/li-wen/avatar_ws_backup_2/install/xarm_description/share/xarm_description/meshes/xarm6/visual/link2_from_stl.obj"/>
      </geometry>
      <origin rpy="0 0 0" xyz="0 0 0"/>
    </collision>
  </link>
  <joint name="xarm6_joint2" type="revolute">
    <parent link="xarm6_link1"/>
    <child link="xarm6_link2"/>
    <origin rpy="-1.5708 0 0" xyz="0 0 0"/>
    <axis xyz="0 0 1"/>
    <limit effort="50.0" lower="-2.059" upper="2.0944" velocity="3.14"/>
    <dynamics damping="1.0" friction="1.0"/>
  </joint>
  <link name="xarm6_link3">
    <inertial>
      <origin rpy="0 0 0" xyz="0.07041 0.11631 0.0107"/>
      <mass value="1.875"/>
      <inertia ixx="0.0063483" ixy="-0.0015397" ixz="0.00096858" iyy="0.00379758" iyz="0.00186567" izz="0.00595768"/>
    </inertial>
    <visual>
      <geometry>
        <mesh filename="file:///home/li-wen/avatar_ws_backup_2/install/xarm_description/share/xarm_description/meshes/xarm6/visual/link3_from_stl.obj"/>
      </geometry>
      <origin rpy="0 0 0" xyz="0 0 0"/>
      <material name="xarm6_White"/>
    </visual>
    <collision>
      <geometry>
        <mesh filename="file:///home/li-wen/avatar_ws_backup_2/install/xarm_description/share/xarm_description/meshes/xarm6/visual/link3_from_stl.obj"/>
      </geometry>
      <origin rpy="0 0 0" xyz="0 0 0"/>
    </collision>
  </link>
  <joint name="xarm6_joint3" type="revolute">
    <parent link="xarm6_link2"/>
    <child link="xarm6_link3"/>
    <origin rpy="0 0 0" xyz="0.0535 -0.2845 0"/>
    <axis xyz="0 0 1"/>
    <limit effort="32.0" lower="-3.927" upper="0.19198" velocity="3.14"/>
    <dynamics damping="1.0" friction="1.0"/>
  </joint>
  <link name="xarm6_link4">
    <inertial>
      <origin rpy="0 0 0" xyz="-0.00018 0.01798 -0.02291"/>
      <mass value="1.3192"/>
      <inertia ixx="0.004896" ixy="-6.925e-06" ixz="-1.418e-05" iyy="0.00445694" iyz="-0.00023186" izz="0.00134332"/>
    </inertial>
    <visual>
      <geometry>
        <mesh filename="file:///home/li-wen/avatar_ws_backup_2/install/xarm_description/share/xarm_description/meshes/xarm6/visual/link4_from_stl.obj"/>
      </geometry>
      <origin rpy="0 0 0" xyz="0 0 0"/>
      <material name="xarm6_White"/>
    </visual>
    <collision>
      <geometry>
        <mesh filename="file:///home/li-wen/avatar_ws_backup_2/install/xarm_description/share/xarm_description/meshes/xarm6/visual/link4_from_stl.obj"/>
      </geometry>
      <origin rpy="0 0 0" xyz="0 0 0"/>
    </collision>
  </link>
  <joint name="xarm6_joint4" type="revolute">
    <parent link="xarm6_link3"/>
    <child link="xarm6_link4"/>
    <origin rpy="-1.5708 0 0" xyz="0.0775 0.3425 0"/>
    <axis xyz="0 0 1"/>
    <limit effort="32.0" lower="-6.283185307179586" upper="6.283185307179586" velocity="3.14"/>
    <dynamics damping="1.0" friction="1.0"/>
  </joint>
  <link name="xarm6_link5">
    <inertial>
      <origin rpy="0 0 0" xyz="0.0651 0.03096 0.00315"/>
      <mass value="1.33854"/>
      <inertia ixx="0.00146378" ixy="-0.000450624" ixz="0.000284306" iyy="0.00184192" iyz="0.000130866" izz="0.002333524"/>
    </inertial>
    <visual>
      <geometry>
        <mesh filename="file:///home/li-wen/avatar_ws_backup_2/install/xarm_description/share/xarm_description/meshes/xarm6/visual/link5_from_stl.obj"/>
      </geometry>
      <origin rpy="0 0 0" xyz="0 0 0"/>
      <material name="xarm6_White"/>
    </visual>
    <collision>
      <geometry>
        <mesh filename="file:///home/li-wen/avatar_ws_backup_2/install/xarm_description/share/xarm_description/meshes/xarm6/visual/link5_from_stl.obj"/>
      </geometry>
      <origin rpy="0 0 0" xyz="0 0 0"/>
    </collision>
  </link>
  <joint name="xarm6_joint5" type="revolute">
    <parent link="xarm6_link4"/>
    <child link="xarm6_link5"/>
    <origin rpy="1.5708 0 0" xyz="0 0 0"/>
    <axis xyz="0 0 1"/>
    <limit effort="32.0" lower="-1.69297" upper="3.141592653589793" velocity="3.14"/>
    <dynamics damping="1.0" friction="1.0"/>
  </joint>
  <link name="xarm6_link6">
    <inertial>
      <origin rpy="0 0 0" xyz="0 -0.00677 -0.01098"/>
      <mass value="0.17"/>
      <inertia ixx="9.3e-05" ixy="-0.0" ixz="-0.0" iyy="5.87e-05" iyz="-3.6e-06" izz="0.000132"/>
    </inertial>
    <visual>
      <geometry>
        <mesh filename="file:///home/li-wen/avatar_ws_backup_2/install/xarm_description/share/xarm_description/meshes/xarm6/visual/link6_from_stl.obj"/>
      </geometry>
      <origin rpy="0 0 0" xyz="0 0 0"/>
      <material name="xarm6_Silver"/>
    </visual>
    <collision>
      <geometry>
        <mesh filename="file:///home/li-wen/avatar_ws_backup_2/install/xarm_description/share/xarm_description/meshes/end_tool/collision/end_tool_from_stl.obj"/>
      </geometry>
      <origin rpy="0 0 0" xyz="0 0 0"/>
    </collision>
  </link>
  <joint name="xarm6_joint6" type="revolute">
    <parent link="xarm6_link5"/>
    <child link="xarm6_link6"/>
    <origin rpy="-1.5708 0 0" xyz="0.076 0.097 0"/>
    <axis xyz="0 0 1"/>
    <limit effort="20.0" lower="-6.283185307179586" upper="6.283185307179586" velocity="3.14"/>
    <dynamics damping="1.0" friction="1.0"/>
  </joint>
  <!-- xarm transmission list -->
  <!--added by LiWen on Apr 17 2025 -->
  <transmission name="xarm6_joint1_transmission">
    <type>sr_mechanism_model/SimpleTransmission</type>
    <actuator name="xarm6_J1">
      <mechanicalReduction>1</mechanicalReduction>
    </actuator>
    <joint name="xarm6_joint1">
      <hardwareInterface>EffortJointInterface</hardwareInterface>
      <hardwareInterface>PositionJointInterface</hardwareInterface>
    </joint>
  </transmission>
  <transmission name="xarm6_joint2_transmission">
    <type>sr_mechanism_model/SimpleTransmission</type>
    <actuator name="xarm6_J2">
      <mechanicalReduction>1</mechanicalReduction>
    </actuator>
    <joint name="xarm6_joint2">
      <hardwareInterface>EffortJointInterface</hardwareInterface>
      <hardwareInterface>PositionJointInterface</hardwareInterface>
    </joint>
  </transmission>
  <transmission name="xarm6_joint3_transmission">
    <type>sr_mechanism_model/SimpleTransmission</type>
    <actuator name="xarm6_J3">
      <mechanicalReduction>1</mechanicalReduction>
    </actuator>
    <joint name="xarm6_joint3">
      <hardwareInterface>EffortJointInterface</hardwareInterface>
      <hardwareInterface>PositionJointInterface</hardwareInterface>
    </joint>
  </transmission>
  <transmission name="xarm6_joint4_transmission">
    <type>sr_mechanism_model/SimpleTransmission</type>
    <actuator name="xarm6_J4">
      <mechanicalReduction>1</mechanicalReduction>
    </actuator>
    <joint name="xarm6_joint4">
      <hardwareInterface>EffortJointInterface</hardwareInterface>
      <hardwareInterface>PositionJointInterface</hardwareInterface>
    </joint>
  </transmission>
  <transmission name="xarm6_joint5_transmission">
    <type>sr_mechanism_model/SimpleTransmission</type>
    <actuator name="xarm6_J5">
      <mechanicalReduction>1</mechanicalReduction>
    </actuator>
    <joint name="xarm6_joint5">
      <hardwareInterface>EffortJointInterface</hardwareInterface>
      <hardwareInterface>PositionJointInterface</hardwareInterface>
    </joint>
  </transmission>
  <transmission name="xarm6_joint6_transmission">
    <type>sr_mechanism_model/SimpleTransmission</type>
    <actuator name="xarm6_J6">
      <mechanicalReduction>1</mechanicalReduction>
    </actuator>
    <joint name="xarm6_joint6">
      <hardwareInterface>EffortJointInterface</hardwareInterface>
      <hardwareInterface>PositionJointInterface</hardwareInterface>
    </joint>
  </transmission>
  <!-- end of xarm transmission list -->
  
  <!-- <link name="${prefix}link_eef" />
    <joint name="${prefix}joint_eef" type="fixed">
      <origin xyz="0 0 0" rpy="0 0 0" />
      <parent link="${prefix}link6" />
      <child link="${prefix}link_eef" />
    </joint> -->
  <!-- Neck Cam Assm Link - bbox -->
  <link name="neck_cam_assm_mount">
    <visual>
      <origin rpy="0 0 0" xyz="0 0 -0.065"/>
      <geometry>
        <box size="0.055 0.12 0.15"/>
      </geometry>
    </visual>
    <collision>
      <origin rpy="0 0 0" xyz="0 0 -0.065"/>
      <geometry>
        <box size="0.055 0.12 0.155"/>
      </geometry>
    </collision>
  </link>
  <joint name="neck_cam_assm_mount" type="fixed">
    <parent link="xarm6_link6"/>
    <child link="neck_cam_assm_mount"/>
    <origin rpy="1.57 -1.57 0.0" xyz="0.0 -0.1067 0.0225"/>
    <!-- -0.1067 physically measured with calipers from xarm ee center to fish-eye lens -->
  </joint>
  <!-- Neck Cam - consistent with hmd_reconciled means z-forward, x-down, y-left-->
  <link name="neck_cam_assm"/>
  <joint name="neck_cam_assm" type="fixed">
    <parent link="neck_cam_assm_mount"/>
    <child link="neck_cam_assm"/>
    <origin rpy="0 0 3.14" xyz="0.0 0.0 0.0"/>
  </joint>
  <link name="neck_cam_left_eye"/>
  <joint name="neck_cam_left_eye" type="fixed">
    <parent link="neck_cam_assm"/>
    <child link="neck_cam_left_eye"/>
    <origin rpy="0 0 0" xyz="0.0 0.034 0.0"/>
  </joint>
  <link name="neck_cam_right_eye"/>
  <joint name="neck_cam_right_eye" type="fixed">
    <parent link="neck_cam_assm"/>
    <child link="neck_cam_right_eye"/>
    <origin rpy="0 0 0" xyz="0.0 -0.034 0.0"/>
  </joint>
  
</robot>
